<?xml version="1.0"?>
<robot xmlns:xacro = "http://www.ros.org/wiki/xacro" name = "Robot">


    <xacro:include filename = "inertial.xacro"/>
    <xacro:include filename = "gazebo_control.xacro"/>



    

                                                        <!--    ALL DIMENSIONS    -->

                                                        <!-- MAIN BODY DIMENSIONS -->

    <xacro:property name = "main_body_length" value = "0.200"/>
    <xacro:property name = "main_body_breadth" value = "0.200"/>
    <xacro:property name = "main_body_height" value = "0.100"/>
    <xacro:property name = "main_body_mass" value = "0.300"/>
    <xacro:property name = "main_body_y_offset" value = "0.100"/>
    <xacro:property name = "main_body_joint_z_offset" value = "0.020"/>
    <xacro:property name = "main_body_z_offset" value = "0.050"/>



                                                        <!--  WHEEL DIMENSIONS  -->

    <xacro:property name = "wheel_dia" value = "0.120"/>
    <xacro:property name = "wheel_width" value = "0.005"/>
    <xacro:property name = "wheel_mass" value = "0.090"/>
    <xacro:property name = "wheel_x_offset" value = "0.1045"/>   <!-- 100 + 5/2 = 102.5 + 2 -->
    <xacro:property name = "wheel_y_offset" value = "0.065"/>



                                                            <!-- CASTER DIMENSIONS -->

    <xacro:property name = "caster_radius" value = "0.020"/>
    <xacro:property name = "caster_y_offset" value = "0.161"/>
    <xacro:property name = "caster_mass" value = "0.400"/>



                                                            <!-- LIDAR DIMENSIONS -->

    <xacro:property name = "lidar_y_offset" value = "0.150"/>
    <xacro:property name = "lidar_z_offset" value = "0.160"/>
    <xacro:property name = "lidar_mass" value = "0.050"/>



                                                            <!-- CAMERA DIMENSIONS -->

    <xacro:property name = "camera_y_offset" value = "0.200"/>
    <xacro:property name = "camera_z_offset" value = "0.050"/>


                                                            <!-- MATERIALS -->
    
    <material name = "gunmetal_grey">
        <color rgba = "0.5647 0.568627 0.5647 1.0"/>
    </material>

    <material name = "metallic_grey">
        <color rgba = "0.505882353 0.521568627 0.537254902 1.0"/>
    </material>

    <material name = "black">
        <color rgba = "0.254 0.254 0.254 0.7"/>
    </material>






                                                            <!-- BASE LINK -->

    <link name = "base_link"/>


                                                            <!-- MAIN BODY -->

    <joint name = "main_body_joint" type = "fixed">
        <parent link="base_link"/>
        <child link="main_body_link"/>
        <origin xyz="0.0 0.0 ${main_body_joint_z_offset}" rpy="0.0 0.0 0.0"/>
    </joint>

    <link name = "main_body_link" >
        <visual>
            <origin xyz="0.0 ${main_body_y_offset} ${main_body_z_offset}" rpy="0.0 0.0 0.0"/>
            <geometry>
                <box size="${main_body_length} ${main_body_breadth} ${main_body_height}"/>
            </geometry>
            <material name = "gunmetal_grey"/>
        </visual>
        <collision>
            <origin xyz="0.0 ${main_body_y_offset} ${main_body_z_offset}" rpy="0.0 0.0 0.0"/>
            <geometry>
                <box size="${main_body_length} ${main_body_breadth} ${main_body_height}"/>
            </geometry>
        </collision>
        <xacro:main_body_inertia mass = "${main_body_mass}" x = "0.200" y = "0.200" z = "0.100">
            <origin xyz="0.0 ${main_body_y_offset} ${main_body_z_offset}" rpy="0.0 0.0 0.0"/>
        </xacro:main_body_inertia>
    </link>

    <gazebo reference = "main_body_link">
        <material>Gazebo/GunmetalGrey</material>
    </gazebo>





                                                            <!--  WHEELS  -->


    <joint name="left_wheel_joint" type="continuous">
        <parent link="main_body_link"/>
        <child link="left_wh_link"/>
        <origin xyz="-${wheel_x_offset} ${wheel_y_offset} 0.04" rpy=" 0.0 -${pi/2} 0.0"/>
        <axis xyz = "0 0 1"/>
    </joint>

    <link name = "left_wh_link" >
        <visual>
            <origin xyz="0.0 0.0 0.0" rpy="0.0 0.0 0.0"/>
            <geometry>
                <cylinder radius="${wheel_dia/2}" length="${wheel_width}"/>
            </geometry>
            <material name = "black" />
        </visual>
        <collision>
            <origin xyz="0.0 0.0 0.0" rpy="0.0 0.0 0.0"/>
            <geometry>
                <cylinder radius="${wheel_dia/2}" length="${wheel_width}"/>
            </geometry>
        </collision>
        <xacro:wheel_inertia mass = "${wheel_mass}" length = "${wheel_width}" radius="${wheel_dia/2}">
            <origin xyz="0 0 0" rpy="0.0 ${pi/2} 0.0"/>
        </xacro:wheel_inertia>
    </link>

    <gazebo reference="left_wh_link">
        <material>Gazebo/Black</material>
        <dynamics damping="0.01" friction="0.1"/>
        <surface>
            <friction>
                <ode>
                    <mu>1.50</mu>
                    <mu2>1.50</mu2>
                </ode>
            </friction>
        </surface>
    </gazebo>



    <joint name="right_wheel_joint" type="continuous">
        <parent link="main_body_link"/>
        <child link="right_wh_link"/>
        <origin xyz="${wheel_x_offset} ${wheel_y_offset} 0.04" rpy=" 0.0 ${pi/2} 0.0"/>
        <axis xyz="0.0 0.0 -1.0"/>
    </joint>

    <link name = "right_wh_link" >
        <visual>
            <geometry>
                <cylinder radius="${wheel_dia/2}" length="${wheel_width}"/>
            </geometry>
            <material name = "black" />
        </visual>
        <collision>
            <origin xyz="0.0 0.0 0.0" rpy="0.0 0.0 0.0"/>
            <geometry>
                <cylinder radius="${wheel_dia/2}" length="${wheel_width}"/>
            </geometry>
        </collision>
        <xacro:wheel_inertia mass = "${wheel_mass}" length = "${wheel_width}" radius="${wheel_dia/2}">
            <origin xyz="0 0 0" rpy="0.0 ${pi/2} 0.0"/>
        </xacro:wheel_inertia>
    </link>

    <gazebo reference="right_wh_link">
        <material>Gazebo/Black</material>
        <dynamics damping="0.01" friction="0.1"/>
        <surface>
            <friction>
                <ode>
                    <mu>1.50</mu>
                    <mu2>1.50</mu2>
                </ode>
            </friction>
        </surface>
    </gazebo>




                                                                <!-- CASTER WHEEL -->
    
    <joint name = "caster_joint" type = "fixed">
        <parent link="main_body_link"/>
        <child link="caster_link"/>
        <origin xyz="0.0 ${caster_y_offset} 0.0" rpy="0.0 0.0 0.0"/>
    </joint>

    <link name = "caster_link" >
        <visual>
            <geometry>
                <sphere radius="${caster_radius}"/>
            </geometry>
            <material name = "metallic_grey"/>
        </visual>
        <collision>
            <geometry>
                <sphere radius="${caster_radius}"/>
            </geometry>
        </collision>
        <xacro:inertial_sphere mass="${caster_mass}" radius="${caster_radius}">
            <origin xyz="0 0 0" rpy="0 0 0"/>
        </xacro:inertial_sphere>
    </link>

    <gazebo reference = "caster_link">
        <material>Gazebo/MettalicGrey</material>
        <mu1 value="0.01"/>
        <mu2 value="0.01"/>
    </gazebo>



                                                                <!-- LIDAR -->

    <joint name="laser_joint" type="fixed">
        <parent link="main_body_link"/>
        <child link="laser_frame"/>
        <origin xyz="0 ${lidar_y_offset} ${lidar_z_offset}" rpy="0 0 0"/>
    </joint>

    <link name="laser_frame">
        <visual>
            <geometry>
                <cylinder radius="0.05" length="0.04"/>
            </geometry>
            <material name="black"/>
        </visual>
        <collision>
            <geometry>
                <cylinder radius="0.05" length="0.04"/>
            </geometry>
        </collision>
        <xacro:inertial_cylinder mass="${lidar_mass}" length="0.04" radius="0.05">
            <origin xyz="0 0 0" rpy="0 0 0"/>
        </xacro:inertial_cylinder>
    </link>



    <gazebo reference="laser_frame">
        <material>Gazebo/Black</material>

        <sensor name="laser" type="ray">
            <pose> 0 0 0 0 0 0 </pose>
            <visualize>true</visualize>
            <update_rate>100</update_rate>
            <ray>
                <scan>
                    <horizontal>
                        <samples>360</samples>
                        <min_angle>-3.14</min_angle>
                        <max_angle>3.14</max_angle>
                    </horizontal>
                </scan>
                <range>
                    <min>0.2</min>
                    <max>12</max>
                </range>
            </ray>
            <plugin name="laser_controller" filename="libgazebo_ros_ray_sensor.so">
                <ros>
                    <argument>~/out:=scan</argument>
                </ros>
                <output_type>sensor_msgs/LaserScan</output_type>
                <frame_name>laser_frame</frame_name>
            </plugin>
        </sensor>
    </gazebo>



                                                                    <!-- CAMERA -->

    <joint name="camera_joint" type="fixed">
        <parent link="main_body_link"/>
        <child link="camera_link"/>
        <origin xyz="0.0 ${camera_y_offset} ${camera_z_offset}" rpy="0 0 0"/>
    </joint>

    <link name="camera_link">
        <visual>
            <geometry>
                <box size="0.03 0.010 0.03"/>
            </geometry>
            <material name="black"/>
        </visual>
    </link>


    <joint name="camera_optical_joint" type="fixed">
        <parent link="camera_link"/>
        <child link="camera_link_optical"/>
        <origin xyz="0 0 0" rpy="-${pi/2} 0 0"/>
    </joint>

    <link name="camera_link_optical">
    </link>



    <gazebo reference="camera_link">
        <material>Gazebo/Black</material>

        <sensor name="camera" type="camera">
            <pose> 0 0 0 0 0 0 </pose>
            <visualize>true</visualize>
            <update_rate>10</update_rate>
            <camera>
                <horizontal_fov>1.089</horizontal_fov>
                <image>
                    <format>R8G8B8</format>
                    <width>640</width>
                    <height>480</height>
                </image>
                <clip>
                    <near>0.05</near>
                    <far>8.0</far>
                </clip>
            </camera>
            <plugin name="camera_controller" filename="libgazebo_ros_camera.so">
                <frame_name>camera_link_optical</frame_name>
            </plugin>
        </sensor>
    </gazebo>

</robot>
